Workbook

Sheet Leads
A1: # | B1: Score | C1: Nome da empresa | D1: Tipo | E1: Segmento | F1: Cidade | G1: Estado | H1: Bairro | I1: Endereco | J1: Telefone (formatado) | K1: WhatsApp | L1: Tem WhatsApp? | M1: Delivery | N1: Plataformas | O1: Nota | P1: Avaliacoes | Q1: Site | R1: Google Maps | S1: Por que entrou | T1: Ressalvas
A2: 1 | B2: 96 | C2: Restaurante Japonês - Kazoku Sushi Delivery SBC | D2: Rede/franquia (5 unidades na base) | E2: Restaurante japonês | F2: São Bernardo do Campo | G2: SP | H2: Alvarenga | I2: Estrada do Poney Club, 1386 - Alvarenga, São Bernardo do Campo - SP, 09853-005, Brasil | J2: (11) 97391-2562 | K2: +5511973912562 | L2: Sim | M2: Sim (perfil Google) | O2: 4.8 | P2: 347 | Q2: https://www.instagram.com/kazokusushisbc/ | R2: abrir | S2: celular (WhatsApp provavel); perfil do Google marca entrega; 347 avaliacoes: porte na faixa da oferta; nota 4.8; 5 unidades encontradas na varredura: rede; site proprio
A3: 2 | B3: 96 | C3: Restaurante Japonês - SAM TEMAKERIA | D3: Rede/franquia (5 unidades na base) | E3: Restaurante japonês | F3: Osasco | G3: SP | H3: Helena Maria | I3: R. Pres. Costa e Silva, 150 - Helena Maria, Osasco - SP, 06253-000, Brasil | J3: (11) 92040-1982 | K3: +5511920401982 | L3: Sim | M3: Sim (perfil Google) | O3: 4.3 | P3: 198 | Q3: https://samtemakeria.alloy.al/samtemakeria/pedidos | R3: abrir | S3: celular (WhatsApp provavel); perfil do Google marca entrega; 198 avaliacoes: porte na faixa da oferta; nota 4.3; 5 unidades encontradas na varredura: rede; site proprio
A4: 3 | B4: 91 | C4: The Best Açaí - Santos Embaré | D4: Franquia (marca conhecida) | E4: Loja de açaí | F4: Santos | G4: SP | H4: Embaré | I4: Av. Dr. Epitácio Pessoa, 161 - Embaré, Santos - SP, 11040-095, Brasil | J4: (13) 99182-5328 | K4: +5513991825328 | L4: Sim | M4: Sim (perfil Google) | O4: 4.9 | P4: 152 | R4: abrir | S4: celular (WhatsApp provavel); perfil do Google marca entrega; 152 avaliacoes: porte na faixa da oferta; nota 4.9; unidade de franquia de porte medio
A5: 4 | B5: 91 | C5: Restaurante Japonês - LU E CAROL YAKISOBA | D5: Rede/franquia (5 unidades na base) | E5: Restaurante japonês | F5: Osasco | G5: SP | H5: Helena Maria | I5: R. Eurípedes de Paula, 04 - Helena Maria, Osasco - SP, 06250-020, Brasil | J5: (11) 95195-3596 | K5: +5511951953596 | L5: Sim | M5: Sim (perfil Google) | O5: 4.5 | P5: 144 | R5: abrir | S5: celular (WhatsApp provavel); perfil do Google marca entrega; 144 avaliacoes: porte na faixa da oferta; nota 4.5; 5 unidades encontradas na varredura: rede
A6: 5 | B6: 85 | C6: Pizzeria Caliari | D6: Independente | E6: Pizzaria | F6: Osasco | G6: SP | H6: Vila Campesina | I6: Av. Dr. Carlos de Moraes Barros, 115 - Vila Campesina, Osasco - SP, 06023-000, Brasil | J6: (11) 97467-1516 | K6: +5511974671516 | L6: Sim | M6: Confirmado (plataforma) | N6: Menudino | O6: 4.8 | P6: 784 | Q6: https://pizzeriacaliari.menudino.com/ | R6: abrir | S6: celular (WhatsApp provavel); vende em Menudino; 784 avaliacoes: porte na faixa da oferta; nota 4.8
A7: 6 | B7: 85 | C7: Pizzaria e Restaurante Pedrinho's | D7: Independente | E7: Pizzaria | F7: Santos | G7: SP | H7: Saboó | I7: Zap ( 41 - 99187.8271 - Saboó, Santos - SP, 11085-180, Brasil | J7: (13) 99720-0688 | K7: +5513997200688 | L7: Sim | M7: Confirmado (plataforma) | N7: Anota AI | O7: 4.4 | P7: 497 | Q7: https://app.anota.ai/m/HEuKM_3ul | R7: abrir | S7: celular (WhatsApp provavel); vende em Anota AI; 497 avaliacoes: porte na faixa da oferta; nota 4.4
A8: 7 | B8: 85 | C8: 200 Burgers | D8: Independente | E8: Hamburgueria | F8: São Bernardo do Campo | G8: SP | H8: Centro | I8: R. Quirino de Lima, 186 - Centro, São Bernardo do Campo - SP, 09715-370, Brasil | J8: (11) 93031-8490 | K8: +5511930318490 | L8: Sim | M8: Confirmado (plataforma) | N8: Cardapio Web | O8: 4.8 | P8: 269 | Q8: https://app.cardapioweb.com/200_burgers#promocoes | R8: abrir | S8: celular (WhatsApp provavel); vende em Cardapio Web; 269 avaliacoes: porte na faixa da oferta; nota 4.8
A9: 8 | B9: 85 | C9: Meu Burguer 013 | Hamburgueria | D9: Independente | E9: Hamburgueria | F9: Santos | G9: SP | H9: Marapé | I9: R. Joaquim Távora, 518 - Marapé, Santos - SP, 11075-301, Brasil | J9: (13) 99724-7906 | K9: +5513997247906 | L9: Sim | M9: Confirmado (plataforma) | N9: Cardapio Web | O9: 4.9 | P9: 140 | Q9: https://app.cardapioweb.com/meu_burguer | R9: abrir | S9: celular (WhatsApp provavel); vende em Cardapio Web; 140 avaliacoes: porte na faixa da oferta; nota 4.9
A10: 9 | B10: 85 | C10: Pastelaria Praça Da Batata | D10: Independente | E10: Sanduicheria | F10: Osasco | G10: SP | H10: Mutinga | I10: R. Jaspe, 64 - Mutinga, Osasco - SP, 06280-210, Brasil | J10: (11) 96431-2256 | K10: +5511964312256 | L10: Sim | M10: Confirmado (plataforma) | N10: Goomer | O10: 4.7 | P10: 87 | Q10: https://www.goomer.app/pastelaria-praca-da-batata | R10: abrir | S10: celular (WhatsApp provavel); vende em Goomer; 87 avaliacoes: porte na faixa da oferta; nota 4.7
A11: 10 | B11: 82 | C11: Restaurante Japonês - SUSHI SÃO BERNARDO | D11: Rede/franquia (5 unidades na base) | E11: Restaurante japonês | F11: São Bernardo do Campo | G11: SP | H11: Bairro dos Casa | I11: Estr. dos Casa, 2927 - Bairro dos Casa, São Bernardo do Campo - SP, 09840-088, Brasil | J11: (11) 94947-6663 | K11: +5511949476663 | L11: Sim | M11: Sim (perfil Google) | O11: 2.4 | P11: 44 | Q11: http://facebook.com/sushis%C3%A3obernardo | R11: abrir | S11: celular (WhatsApp provavel); perfil do Google marca entrega; 44 avaliacoes; 5 unidades encontradas na varredura: rede; site proprio | T11: nota baixa (2.4)
A12: 11 | B12: 81 | C12: Empório do Pastel | D12: Independente | E12: Restaurante | F12: Osasco | G12: SP | H12: Rochdale | I12: R. Agudos, 593 - Rochdale, Osasco - SP, 06223-140, Brasil | J12: (11) 97432-9185 | K12: +5511974329185 | L12: Sim | M12: Sim (perfil Google) | O12: 4.3 | P12: 896 | Q12: http://www.emporiodopastel.com.br/ | R12: abrir | S12: celular (WhatsApp provavel); perfil do Google marca entrega; 896 avaliacoes: porte na faixa da oferta; nota 4.3; site proprio
A13: 12 | B13: 81 | C13: Pastel do Akira | D13: Independente | E13: Pastelaria brasileira | F13: Santos | G13: SP | H13: Ponta da Praia | I13: R. Ver. Henrique Soler, 286 - Ponta da Praia, Santos - SP, 11030-010, Brasil | J13: (13) 99111-9505 | K13: +5513991119505 | L13: Sim | M13: Sim (perfil Google) | O13: 4.6 | P13: 855 | Q13: http://www.instagram.com/pastel.do.akira | R13: abrir | S13: celular (WhatsApp provavel); perfil do Google marca entrega; 855 avaliacoes: porte na faixa da oferta; nota 4.6; site proprio
A14: 13 | B14: 81 | C14: Tropeço Lanches | D14: Independente | E14: Lanchonete | F14: Santos | G14: SP | H14: Boqueirão | I14: Av. Bartholomeu de Gusmão, 0 - Boqueirão, Santos - SP, 11045-400, Brasil | J14: (13) 98801-0232 | K14: +5513988010232 | L14: Sim | M14: Sim (perfil Google) | O14: 4.5 | P14: 573 | Q14: https://instagram.com/tropecolanches?utm_medium=copy_link | R14: abrir | S14: celular (WhatsApp provavel); perfil do Google marca entrega; 573 avaliacoes: porte na faixa da oferta; nota 4.5; site proprio
A15: 14 | B15: 81 | C15: Hamburgueria do Fusca | D15: Independente | E15: Hamburgueria | F15: Santos | G15: SP | H15: Embaré | I15: R. Galeão Coutinho, 454 - Embaré, Santos - SP, 11040-210, Brasil | J15: (13) 99183-8160 | K15: +5513991838160 | L15: Sim | M15: Sim (perfil Google) | O15: 4.8 | P15: 557 | Q15: http://www.hamburgueriadofusca.com.br/ | R15: abrir | S15: celular (WhatsApp provavel); perfil do Google marca entrega; 557 avaliacoes: porte na faixa da oferta; nota 4.8; site proprio
A16: 15 | B16: 81 | C16: Wilmar Lanches | D16: Independente | E16: Restaurante | F16: Santos | G16: SP | H16: Embaré | I16: Pr - Av. Bartholomeu de Gusmão, S/N - Embaré, Santos - SP, 11045-400, Brasil | J16: (13) 99630-0589 | K16: +5513996300589 | L16: Sim | M16: Sim (perfil Google) | O16: 4.4 | P16: 466 | Q16: https://instabio.cc/wilmarlanches | R16: abrir | S16: celular (WhatsApp provavel); perfil do Google marca entrega; 466 avaliacoes: porte na faixa da oferta; nota 4.4; site proprio
A17: 16 | B17: 81 | C17: El Magnifico - Osasco | D17: Independente | E17: Delivery | G17: SP | J17: (11) 98567-9285 | K17: +5511985679285 | L17: Sim | M17: Sim (perfil Google) | O17: 4.1 | P17: 376 | Q17: http://www.instagram.com/elmagnificoburger_ | R17: abrir | S17: celular (WhatsApp provavel); perfil do Google marca entrega; 376 avaliacoes: porte na faixa da oferta; nota 4.1; site proprio
A18: 17 | B18: 81 | C18: Bonna Pizza Santos | D18: Independente | E18: Pizzaria | F18: Santos | G18: SP | H18: Marapé | I18: R. Carvalho de Mendonça, 771 - Marapé, Santos - SP, 11070-103, Brasil | J18: (13) 98137-8996 | K18: +5513981378996 | L18: Sim | M18: Sim (perfil Google) | O18: 4.6 | P18: 325 | Q18: https://www.instagram.com/bonna_pizzaria/ | R18: abrir | S18: celular (WhatsApp provavel); perfil do Google marca entrega; 325 avaliacoes: porte na faixa da oferta; nota 4.6; site proprio
A19: 18 | B19: 81 | C19: Casa da Vó Marmitex | D19: Independente | E19: Restaurante | F19: São Bernardo do Campo | G19: SP | H19: Bairro dos Casa | I19: Rua Senador Edson Cavalcanti, 29 - Bairro dos Casa, São Bernardo do Campo - SP, 09850-060, Brasil | J19: (11) 99392-6827 | K19: +5511993926827 | L19: Sim | M19: Sim (perfil Google) | O19: 4.3 | P19: 298 | Q19: https://delivery.yooga.app/restaurante-casa-da-vo | R19: abrir | S19: celular (WhatsApp provavel); perfil do Google marca entrega; 298 avaliacoes: porte na faixa da oferta; nota 4.3; site proprio
A20: 19 | B20: 81 | C20: J.J Restaurante & Lanchonete | D20: Independente | E20: Lanchonete | F20: Osasco | G20: SP | H20: Vila Menck | I20: Av. Pres. Médici, 1625 - Vila Menck, Osasco - SP, 06286-000, Brasil | J20: (11) 94136-8938 | K20: +5511941368938 | L20: Sim | M20: Sim (perfil Google) | O20: 4.6 | P20: 198 | Q20: https://whatsmenu.com.br/11941368938 | R20: abrir | S20: celular (WhatsApp provavel); perfil do Google marca entrega; 198 avaliacoes: porte na faixa da oferta; nota 4.6; site proprio
A21: 20 | B21: 81 | C21: Açaí Delivery Osasco | D21: Independente | E21: Sorveteria | F21: Osasco | G21: SP | H21: Centro | I21: R. Gen. Bittencourt, 487 - Centro, Osasco - SP, 06016-045, Brasil | J21: (11) 93200-5587 | K21: +5511932005587 | L21: Sim | M21: Sim (perfil Google) | O21: 4.5 | P21: 197 | Q21: https://pedido.brendi.com.br/acai-delivery-osasco | R21: abrir | S21: celular (WhatsApp provavel); perfil do Google marca entrega; 197 avaliacoes: porte na faixa da oferta; nota 4.5; site proprio
A22: 21 | B22: 81 | C22: Ih Sushi Bar | D22: Independente | E22: Restaurante japonês | F22: São Bernardo do Campo | G22: SP | H22: Vila Santa Angelina | I22: R. São Geraldo, 340 - Vila Santa Angelina, São Bernardo do Campo - SP, 09820-220, Brasil | J22: (11) 96564-0723 | K22: +5511965640723 | L22: Sim | M22: Sim (perfil Google) | O22: 4.9 | P22: 176 | Q22: https://linktr.ee/ihsushibar | R22: abrir | S22: celular (WhatsApp provavel); perfil do Google marca entrega; 176 avaliacoes: porte na faixa da oferta; nota 4.9; site proprio
A23: 22 | B23: 81 | C23: Bistrô 14 - Doces | D23: Independente | E23: Doceria | F23: Santos | G23: SP | H23: Gonzaga | I23: Av. Anna Costa, 455 - Gonzaga, Santos - SP, 11060-003, Brasil | J23: (13) 99744-1414 | K23: +5513997441414 | L23: Sim | M23: Sim (perfil Google) | O23: 4.8 | P23: 158 | Q23: https://instagram.com/bistro14_?igshid=YmMyMTA2M2Y= | R23: abrir | S23: celular (WhatsApp provavel); perfil do Google marca entrega; 158 avaliacoes: porte na faixa da oferta; nota 4.8; site proprio
A24: 23 | B24: 81 | C24: Marmitaria da Mary | D24: Independente | E24: Delivery | F24: São Bernardo do Campo | G24: SP | H24: Vila Dusi | I24: R. Arthur Corradi, 43 - Vila Dusi, São Bernardo do Campo - SP, 09725-240, Brasil | J24: (11) 98025-9644 | K24: +5511980259644 | L24: Sim | M24: Sim (perfil Google) | O24: 4.8 | P24: 155 | Q24: https://whatsmenu.com.br/marmitariadamary | R24: abrir | S24: celular (WhatsApp provavel); perfil do Google marca entrega; 155 avaliacoes: porte na faixa da oferta; nota 4.8; site proprio
A25: 24 | B25: 81 | C25: Hora do Açaí 013 | D25: Independente | E25: Restaurante | F25: Santos | G25: SP | H25: Marapé | I25: Av. Dr. Moura Ribeiro, 48A - Marapé, Santos - SP, 11070-060, Brasil | J25: (13) 99135-7287 | K25: +5513991357287 | L25: Sim | M25: Sim (perfil Google) | O25: 4.5 | P25: 141 | Q25: https://pt-br.facebook.com/horadoacai013/ | R25: abrir | S25: celular (WhatsApp provavel); perfil do Google marca entrega; 141 avaliacoes: porte na faixa da oferta; nota 4.5; site proprio
A26: 25 | B26: 81 | C26: Sushi Home Santos | Restaurante de comida Japonesa em Santos na Ponta da Praia | D26: Independente | E26: Restaurante japonês | F26: Santos | G26: SP | H26: Ponta da Praia | I26: R. Dr. Egydio Martins, 101 - Ponta da Praia, Santos - SP, 11030-161, Brasil | J26: (13) 99766-7976 | K26: +5513997667976 | L26: Sim | M26: Sim (perfil Google) | O26: 4.8 | P26: 82 | Q26: https://now.swfast.com.br/sushihomesantos/menu | R26: abrir | S26: celular (WhatsApp provavel); perfil do Google marca entrega; 82 avaliacoes: porte na faixa da oferta; nota 4.8; site proprio
A27: 26 | B27: 81 | C27: Marlene Marmitas em Santos | D27: Independente | E27: Serviço de catering | F27: Santos | G27: SP | H27: Vila Belmiro | I27: R. Particular Rio de Janeiro, 132 - Vila Belmiro, Santos - SP, 11075-345, Brasil | J27: (11) 92488-0675 | K27: +5511924880675 | L27: Sim | M27: Sim (perfil Google) | O27: 4.8 | P27: 82 | Q27: http://www.marlenemarmitas.com.br/ | R27: abrir | S27: celular (WhatsApp provavel); perfil do Google marca entrega; 82 avaliacoes: porte na faixa da oferta; nota 4.8; site proprio
A28: 27 | B28: 79 | C28: Issa Sushi Delivery Japonês - Osasco | D28: Independente | E28: Restaurante japonês | F28: Osasco | G28: SP | H28: Presidente Altino | I28: R. Ari Barroso, 215 - Pres. Altino, Osasco - SP, 06216-230, Brasil | J28: (11) 95142-7647 | K28: +5511951427647 | L28: Sim | M28: Confirmado (plataforma) | N28: Anota AI | O28: 4.9 | P28: 60 | Q28: https://pedido.anota.ai/loja/issa-sushi-delivery-1 | R28: abrir | S28: celular (WhatsApp provavel); vende em Anota AI; 60 avaliacoes; nota 4.9
A29: 28 | B29: 79 | C29: BIGLOW EXPRESS | D29: Independente | E29: Hamburgueria | F29: São Bernardo do Campo | G29: SP | H29: number:1678544 | I29: Estr. do Rio Acima, 572 - number:1678544, São Bernardo do Campo - SP, 09830-100, Brasil | J29: (11) 96443-8602 | K29: +5511964438602 | L29: Sim | M29: Confirmado (plataforma) | N29: Saipos | O29: 4.9 | P29: 52 | Q29: http://biglowexpress.saipos.com/ | R29: abrir | S29: celular (WhatsApp provavel); vende em Saipos; 52 avaliacoes; nota 4.9
A30: 29 | B30: 79 | C30: Açaiteria Mundo Brasileiro | D30: Independente | E30: Loja de açaí | F30: Osasco | G30: SP | H30: Vila Yara | I30: Av. dos Autonomistas, 501 - 503 - Loja 18 - Vila Yara, Osasco - SP, 06020-000, Brasil | J30: (11) 97690-7806 | K30: +5511976907806 | L30: Sim | M30: Confirmado (plataforma) | N30: iFood | O30: 4.9 | P30: 52 | Q30: https://www.ifood.com.br/delivery/sao-paulo-sp/acaiteria-mun | R30: abrir | S30: celular (WhatsApp provavel); vende em iFood; 52 avaliacoes; nota 4.9
A31: 30 | B31: 79 | C31: Açaí do lancaster | D31: Independente | E31: Sorveteria | F31: Santos | G31: SP | H31: Vila Nova | I31: Rua Sete de Setembro, 84 - Vila Nova, Santos - SP, 11013-350, Brasil | J31: (13) 99606-9768 | K31: +5513996069768 | L31: Sim | M31: Confirmado (plataforma) | N31: Anota AI | O31: 4.8 | P31: 31 | Q31: https://pedido.anota.ai/loja/aai-do-lancaster?f=ms | R31: abrir | S31: celular (WhatsApp provavel); vende em Anota AI; 31 avaliacoes; nota 4.8
A32: 31 | B32: 79 | C32: Esfiharia & Pizzaria do Bigode | D32: Independente | E32: Lanchonete | F32: São Bernardo do Campo | G32: SP | H32: Montanhão | I32: R. Carlos Augusto, 255 - Montanhão, São Bernardo do Campo - SP, 09792-200, Brasil | J32: (11) 95997-5330 | K32: +5511959975330 | L32: Sim | M32: Confirmado (plataforma) | N32: iFood | O32: 4.9 | P32: 30 | Q32: https://www.ifood.com.br/delivery/sao-bernardo-do-campo-sp/e | R32: abrir | S32: celular (WhatsApp provavel); vende em iFood; 30 avaliacoes; nota 4.9
A33: 32 | B33: 77 | C33: Ponto da Esfiha- Vila Yara | D33: Independente | E33: Esfiharia | F33: Osasco | G33: SP | H33: Vila Campesina | I33: R. Anselmo Pedro Medeiros, 791 - Vila Campesina, Osasco - SP, 06028-030, Brasil | J33: (11) 98276-7428 | K33: +5511982767428 | L33: Sim | M33: Sim (perfil Google) | O33: 3.9 | P33: 687 | Q33: https://kardapio.app/pontodaesfihavilayara | R33: abrir | S33: celular (WhatsApp provavel); perfil do Google marca entrega; 687 avaliacoes: porte na faixa da oferta; site proprio
A34: 33 | B34: 77 | C34: Sushi Onegai | D34: Independente | E34: Delivery | F34: São Bernardo do Campo | G34: SP | H34: Jardim Tupã | I34: Estr. do Aladino, 18 - Jardim Tupã, São Bernardo do Campo - SP, 09831-525, Brasil | J34: (11) 97836-3197 | K34: +5511978363197 | L34: Sim | M34: Sim (perfil Google) | O34: 5 | P34: 151 | Q34: https://www.instagram.com/sushi_onegai/profilecard/?igsh=MWR | R34: abrir | S34: celular (WhatsApp provavel); perfil do Google marca entrega; 151 avaliacoes: porte na faixa da oferta; site proprio
A35: 34 | B35: 76 | C35: Lanches Barton' s | D35: Independente | E35: Lanchonete | F35: Santos | G35: SP | H35: Gonzaga | I35: Av. Anna Costa, 530 - loja 37 f - Gonzaga, Santos - SP, 11060-002, Brasil | J35: (13) 99745-1679 | K35: +5513997451679 | L35: Sim | M35: Sim (perfil Google) | O35: 4.6 | P35: 288 | R35: abrir | S35: celular (WhatsApp provavel); perfil do Google marca entrega; 288 avaliacoes: porte na faixa da oferta; nota 4.6
A36: 35 | B36: 76 | C36: Big Pastel | D36: Independente | E36: Pastelaria brasileira | F36: São Bernardo do Campo | G36: SP | H36: Parque Sao Bernardo | I36: R. Almeida Leme, 69 - Parque Sao Bernardo, São Bernardo do Campo - SP, 09761-180, Brasil | J36: (11) 94605-5956 | K36: +5511946055956 | L36: Sim | M36: Sim (perfil Google) | O36: 4.6 | P36: 206 | R36: abrir | S36: celular (WhatsApp provavel); perfil do Google marca entrega; 206 avaliacoes: porte na faixa da oferta; nota 4.6
A37: 36 | B37: 76 | C37: Donana Marmitex | D37: Independente | E37: Restaurante | F37: Osasco | G37: SP | H37: Presidente Altino | I37: Rua Oswaldo Collino, 994 - Pres. Altino, Osasco - SP, 06210-005, Brasil | J37: (11) 94056-7839 | K37: +5511940567839 | L37: Sim | M37: Sim (perfil Google) | O37: 4.5 | P37: 170 | R37: abrir | S37: celular (WhatsApp provavel); perfil do Google marca entrega; 170 avaliacoes: porte na faixa da oferta; nota 4.5
A38: 37 | B38: 76 | C38: Disk Pizza Papa Léguas Santos | D38: Independente | E38: Delivery de Pizza | F38: Santos | G38: SP | H38: Marapé | I38: R. Joaquim Távora, 407 - Marapé, Santos - SP, 11075-301, Brasil | J38: (13) 97819-1436 | K38: +5513978191436 | L38: Sim | M38: Sim (perfil Google) | O38: 4.8 | P38: 166 | R38: abrir | S38: celular (WhatsApp provavel); perfil do Google marca entrega; 166 avaliacoes: porte na faixa da oferta; nota 4.8
A39: 38 | B39: 76 | C39: Açaí Bar | D39: Independente | E39: Bar informal | F39: Santos | G39: SP | H39: Bom Retiro | I39: Av. Jovino de Mello, 1328 - Bom Retiro, Santos - SP, 11088-050, Brasil | J39: (13) 98837-5311 | K39: +5513988375311 | L39: Sim | M39: Sim (perfil Google) | O39: 4.8 | P39: 112 | R39: abrir | S39: celular (WhatsApp provavel); perfil do Google marca entrega; 112 avaliacoes: porte na faixa da oferta; nota 4.8
A40: 39 | B40: 76 | C40: Pastel da Isa | D40: Independente | E40: Lanchonete | F40: Santos | G40: SP | H40: Ponta da Praia | I40: Av. Rei Pelé, 111 - Ponta da Praia, Santos - SP, 11030-401, Brasil | J40: (13) 97418-8890 | K40: +5513974188890 | L40: Sim | M40: Sim (perfil Google) | O40: 4.8 | P40: 111 | R40: abrir | S40: celular (WhatsApp provavel); perfil do Google marca entrega; 111 avaliacoes: porte na faixa da oferta; nota 4.8
...

Sheet Resumo
A1: Leads gastronomia + delivery — Barueri, Osasco, Santos, São Bernardo do Campo e mais
A2: Fonte: Google Maps via Apify (compass/crawler-google-places)
A3: Total de leads na planilha | B3: =COUNTA(Leads!A2:A175)
A4: Com celular (WhatsApp provavel) | B4: =COUNTIF(Leads!L2:L175,"Sim") | C4: =IFERROR(B4/$B$3,0)
A5: Delivery confirmado por plataforma de pedido | B5: =COUNTIF(Leads!M2:M175,"Confirmado*") | C5: =IFERROR(B5/$B$3,0)
A6: Entrega marcada no perfil do Google | B6: =COUNTIF(Leads!M2:M175,"Sim*") | C6: =IFERROR(B6/$B$3,0)
A7: Rede ou franquia | B7: =COUNTIF(Leads!D2:D175,"Rede/franquia*")+COUNTIF(Leads!D2:D175,"Franquia*") | C7: =IFERROR(B7/$B$3,0)
A8: Score alto (>=75): comecar por aqui | B8: =COUNTIF(Leads!B2:B175,">=75") | C8: =IFERROR(B8/$B$3,0)
A9: Prontos para abordagem (celular + plataforma de pedido) | B9: =COUNTIFS(Leads!L2:L175,"Sim",Leads!M2:M175,"Confirmado*") | C9: =IFERROR(B9/$B$3,0)
A11: Por cidade
A12: Barueri | B12: =COUNTIF(Leads!F2:F175,A12) | C12: =IFERROR(B12/$B$3,0)
A13: Osasco | B13: =COUNTIF(Leads!F2:F175,A13) | C13: =IFERROR(B13/$B$3,0)
A14: Santos | B14: =COUNTIF(Leads!F2:F175,A14) | C14: =IFERROR(B14/$B$3,0)
A15: São Bernardo do Campo | B15: =COUNTIF(Leads!F2:F175,A15) | C15: =IFERROR(B15/$B$3,0)
A16: São Paulo | B16: =COUNTIF(Leads!F2:F175,A16) | C16: =IFERROR(B16/$B$3,0)
A18: Como usar
A19: • Trabalhe de cima para baixo: a aba Leads ja vem ordenada por score.
A20: • A coluna E.164 e a que entra direto no import de leads do portal.
A21: • WhatsApp? em vermelho = numero fixo. Confira antes de gastar disparo.
A22: • Ressalvas explica o que pesou contra cada lead.
A23: • As contagens acima sao formulas: apague linhas e elas se ajustam.

Sheet Criterio
A1: Fator | B1: Pontos | C1: Por que
A2: Telefone e celular | B2: +30 | C2: 18 dos 82 leads da Mariana morreram como invalid_phone. Numero fixo nao tem WhatsApp.
A3: Telefone fixo | B3: +4 | C3: Fica na lista, mas so vale disparo depois de conferir.
A4: Delivery confirmado (plataforma) | B4: +25 | C4: Site aponta para iFood, Anota AI, Cardapio Web, Goomer, Menudino ou Saipos: operacao digital rodando.
A5: Entrega no perfil do Google | B5: +16 | C5: 81% dos lugares marcam entrega, entao isso qualifica mas quase nao diferencia.
A6: Delivery provavel | B6: +10 | C6: So o nome ou a categoria sugerem entrega.
A7: 80 a 900 avaliacoes | B7: +20 | C7: Faixa de porte da oferta: pequeno e medio que ja vende.
A8: 25 a 79 avaliacoes | B8: +14 | C8: Casa menor, ainda dentro do publico.
A9: 900 a 2500 avaliacoes | B9: +9 | C9: Operacao grande: costuma ja ter stack propria.
A10: Acima de 2500 avaliacoes | B10: +3 | C10: Grande demais para a oferta.
A11: Menos de 25 avaliacoes | B11: +3 | C11: Casa nova ou pouco ativa: risco de nao ter volume.
A12: Nota entre 4,0 e 4,9 | B12: +10 | C12: Operacao cuidada e com gestao presente.
... A16: Rede nacional | B16: -25 | C16: O numero publicado e central ou robo de pedido, e a unidade nao decide sozinha.
A18: Descartados antes do ranking
A19: • Lugares fechados em definitivo ou temporariamente.
A20: • Sem telefone publicado (nao ha como abordar).
A21: • Telefone repetido (a mesma casa aparecendo em varias buscas).
A22: • Categoria fora do ramo (hotel, posto, mercado, farmacia).
